---
title: 手动实现一个Promise
date: 2022-02-28 16:11:05
permalink: /pages/99b3e8/
categories:
  - 源码
tags:
  - Promise
  - Javascript
author: 
  name: 旗木五五开
  link: https://github.com/2513022260
---
# 手动实现一个Promise

基于`Promise/A+`实现一个`Promise`。
手写`Promise`需要考虑很多特殊情况。
我们在实际运用时可能暂时不会碰到这些情况，可是当我们遇到的时候 却不知底层的原理，无法精准定位和解决问题，这就是为什么我们要知道如何手写`Promise`。
<!-- more -->

包含知识点： 
* Promise
* Class 类
* call、apply和bind
* Event Loop
* 发布、订阅

## 术语
* Promise：是一个拥有 then 方法的对象或函数，其行为符合本规范；
* thenable：是一个定义了 then 方法的对象或函数，文中译作“拥有 then 方法”；
* 值（value）：指任何 JavaScript 的合法值（包括 undefined , thenable 和 promise）；
* 异常（exception）：是使用 throw 语句抛出的一个值。
* 据因（reason）：表示一个 promise 的拒绝原因。

## `Promise` 的状态
  * 等待态（Pending）
  * 执行态（Fulfilled）
  * 拒绝态（Rejected）
```js
const PENDING = 'pending'
const FULFILLED = 'fulfilled'
const REJECTED = 'rejected'
```

## `Promise.resolve()`和`Promise.reject()`
1. 原生的promise里面可以传入 `resolve` 和 `reject` 两个参数:
```js
const p = new Promise((resolve, reject) => {})
```
步骤：
* 新建`myPromise`类，添加构造函`constructor`的形参 `fn` 并执行。
* 增加原生方法`resolve` 和 `reject`。
* 将 `resolve` 和 `reject`传入fn。
```js
class myPromise {
  constructor(fn) {
    fn(this.resolve, this.reject)
  }
  resolve() {}
  reject() {}
}
```

2. 状态改变
定义一个`status`，用于表示状态，初始是`pending`
```js
class myPromise {
  constructor(fn) {
    this.status = PENDING
    fn(this.resolve, this.reject)
  }
  resolve() {}
  reject() {}
}
```
那么在执行`resolve()`的时候就需要判断状态是否为`待定pending`，如果是的话就把状态改为 `成功fulfilled`;
同理执行`reject()`的时候，如果判断状态是否为`待定pending`，就把状态改为 `拒绝rejected`。
```js
const PENDING = 'pending'
const FULFILLED = 'fulfilled'
const REJECTED = 'rejected'
class myPromise {
  constructor(fn) {
    this.status = PENDING
    fn(this.resolve, this.reject)
  }
  resolve() {
    if (this.status === PENDING) {
      this.status = FULFILLED
    }
  }
  reject() {
    if (this.status === PENDING) {
      this.status = REJECTED
    }
  }
}
```
resolve()接收一个成功值，reject()接收一个拒因。
```js
const p = new Promise((resolve, reject) => { resolve('成功') })
const p = new Promise((resolve, reject) => { reject('失败') })
```
我们将成功值与拒因分别存入实例的属性`value`和`reason`。
```js
const PENDING = 'pending'
const FULFILLED = 'fulfilled'
const REJECTED = 'rejected'
class myPromise {
  constructor(fn) {
    this.status = PENDING
    this.value = null
    this.reason = null
    fn(this.resolve, this.reject)
  }
  resolve(value) {
    if (this.status === PENDING) {
      this.status = FULFILLED
      this.value = value
    }
  }
  reject(reason) {
    if (this.status === PENDING) {
      this.status = REJECTED
      this.reason = reason
    }
  }
}
```
测试代码，发现报错，`this`丢失。
```js
const p = new myPromise((resolve, reject) => {
  resolve('成功')
})

TypeError: Cannot read property 'status' of undefined
```
通过bind方法，给方法绑定this。
```js
fn(this.resolve.bind(this), this.reject.bind(this))
```

## `Promise.then()` 方法
then是在创建实例后再进行调用的，调用方式：
```js
const p = new myPromise((resolve, reject) => {
  resolve('成功')
})
p.then(resolve => {
  console.log(resolve)
}, reject => {
  console.log(reject)
})
```
一个`promise `必须提供一个`then`方法以访问其当前值、终值和据因。`promise`的`then`方法接受两个参数：
```js
then(onFulfilled, onRejected) {}
```
1. 状态不可变
`Promise` 只会执行`成功状态`或者`拒绝状态`的其中一。也就是我们前文讲到的，`Promise`只以`第一次为准`，第一次成功就永久为`fulfilled`，第一次失败就永远状态为`rejected`。
```js
const p = new Promise((resolve, reject) => {
  resolve('成功')
  reject('失败')
})
p.then(resolve => {
  console.log(resolve)
}, reject => {
  console.log(reject)
})

// 结果：成功
```
```js
const PENDING = 'pending'
const FULFILLED = 'fulfilled'
const REJECTED = 'rejected'
class myPromise {
  constructor(fn) {
    this.status = PENDING
    this.value = null
    this.reason = null
    fn(this.resolve.bind(this), this.reject.bind(this))
  }
  resolve(value) {
    if (this.status === PENDING) {
      this.status = FULFILLED
      this.value = value
    }
  }
  reject(reason) {
    if (this.status === PENDING) {
      this.status = REJECTED
      this.reason = reason
    }
  }
  then(onFulfilled, onRejected) {
    if (this.status === FULFILLED) {
      onFulfilled(this.value)
    }
    if (this.status === REJECTED) {
      onRejected(this.reason)
    }
  }
}
```
2. 执行异常 throw
```js
const promise = new Promise(function(resolve, reject) {
  throw new Error('test')
})
promise.then(resolve => {
  console.log(resolve)
}, reject => {
  console.log(reject)
})
// Error: test
```
上面代码中，promise抛出一个错误，就被`catch()`方法指定的回调函数捕获。通过`try/catch`捕获异常，传给`reject`方法。
```js
try {
  fn(this.resolve.bind(this), this.reject.bind(this))
} catch (error) {
  this.reject(error) 
}
```
3. 参数校验
Promise 规范如果 onFulfilled 和 onRejected 不是函数，就忽略他们，所谓“忽略”并不是什么都不干，对于onFulfilled来说“忽略”就是将value原封不动的返回，对于onRejected来说就是返回reason，onRejected因为是错误分支，我们返回reason应该throw一个Error:
```js
then(onFulfilled, onRejected) {
  onFulfilled = typeof onFulfilled === 'function' ? onFulfilled : value => value // 如果不是function 返回value
  onRejected = typeof onRejected === 'function' ? onRejected : reason => { throw reason }
  if (this.status === FULFILLED) {
    onFulfilled(this.value)
  }
  if (this.status === REJECTED) {
    onRejected(this.reason)
  }
}
```
当前完整代码：
```js
const PENDING = 'pending'
const FULFILLED = 'fulfilled'
const REJECTED = 'rejected'
class myPromise {
  constructor(fn) {
    this.status = PENDING
    this.value = null
    this.reason = null
    try {
      fn(this.resolve.bind(this), this.reject.bind(this))
    } catch (error) {
      this.reject(error) 
    }
  }
  resolve(value) {
    if (this.status === PENDING) {
      this.status = FULFILLED
      this.value = value
    }
  }
  reject(reason) {
    if (this.status === PENDING) {
      this.status = REJECTED
      this.reason = reason
    }
  }
  then(onFulfilled, onRejected) {
    onFulfilled = typeof onFulfilled === 'function' ? onFulfilled : value => value
    onRejected = typeof onRejected === 'function' ? onRejected : reason => { throw reason }
    if (this.status === FULFILLED) {
      onFulfilled(this.value)
    }
    if (this.status === REJECTED) {
      onRejected(this.reason)
    }
  }
}
```


## 实现异步
测试代码：
```js
console.log(1)
const p = new myPromise((resolve, reject) => {
  console.log(2)
  resolve(3)
})
p.then((value) => {
  console.log('value:' + value)
}, (reason) => {
  console.log(reason)
})
console.log(4)

// 目的：
// 1
// 2
// 4
// value:3

// 实际
// 1
// 2
// value:3
// 4
```
1. 添加定时器`setTimeout`，实现异步功能。
```js
then(onFulfilled, onRejected) {
  onFulfilled = typeof onFulfilled === 'function' ? onFulfilled : value => value
  onRejected = typeof onRejected === 'function' ? onRejected : reason => { throw reason }
  if (this.status === FULFILLED) {
    setTimeout(() => {
      onFulfilled(this.value)
    })
  }
  if (this.status === REJECTED) {
    setTimeout(() => {
      onRejected(this.reason)
    })
  }
}
```
2. 函数保存，发布订阅。
```js
console.log(1)
const p = new myPromise((resolve, reject) => {
  setTimeout(() => { // 添加定时器setTimeout
    console.log(2)
    resolve(3)
    console.log(4)
  })
})
p.then((value) => {
  console.log('value:' + value)
}, (reason) => {
  console.log(reason)
})
console.log(5)

// 输出
// 1
// 5
// 2
// 4
```
上述丢失了`resolve`的值3。是因为在执行`then()`前还没有执行`resovle()`，当前还处于`pending`状态。所以我们在执行then的时候，先将方法给存起来。然后再等执行`resolve()`或者`reject()`的时候`foreach`遍历执行。
```js
const PENDING = 'pending'
const FULFILLED = 'fulfilled'
const REJECTED = 'rejected'
class myPromise {
  constructor(fn) {
    this.status = PENDING
    this.value = null
    this.reason = null
    this.onFulfilledCallbacks = []  // 保存成功回调
    this.onRejectedCallbacks = []  // 保存失败回调
    try {
      fn(this.resolve.bind(this), this.reject.bind(this))
    } catch (error) {
      this.reject(error) 
    }
  }
  resolve(value) {
    if (this.status === PENDING) {
      this.status = FULFILLED
      this.value = value
      this.onFulfilledCallbacks.forEach(callback => {
        callback(value)
      })
    }
  }
  reject(reason) {
    if (this.status === PENDING) {
      this.status = REJECTED
      this.reason = reason
      this.onRejectedCallbacks.forEach(callback => {
        callback(reason)
      })
    }
  }
  then(onFulfilled, onRejected) {
    onFulfilled = typeof onFulfilled === 'function' ? onFulfilled : value => value
    onRejected = typeof onRejected === 'function' ? onRejected : reason => { throw reason }
    if (this.status === PENDING) {
      this.onFulfilledCallbacks.push(onFulfilled)
      this.onRejectedCallbacks.push(onRejected)
    }
    if (this.status === FULFILLED) {
      setTimeout(() => {
        onFulfilled(this.value)
      })
    }
    if (this.status === REJECTED) {
      setTimeout(() => {
        onRejected(this.reason)
      })
    }
  }
}
```
这里有一个小细节，`resolve` 和 `reject` 是要在 `事件循环末尾` 执行的，因此我们就 给 `resolve` 和 `reject` 里面加上 `setTimeout` 就可以了。
```js
const PENDING = 'pending'
const FULFILLED = 'fulfilled'
const REJECTED = 'rejected'
class myPromise {
  constructor(fn) {
    this.status = PENDING
    this.value = null
    this.reason = null
    this.onFulfilledCallbacks = []  // 保存成功回调
    this.onRejectedCallbacks = []  // 保存失败回调
    try {
      fn(this.resolve.bind(this), this.reject.bind(this))
    } catch (error) {
      this.reject(error) 
    }
  }
  resolve(value) {
    if (this.status === PENDING) {
      setTimeout(() => {
        this.status = FULFILLED
        this.value = value
        this.onFulfilledCallbacks.forEach(callback => {
          callback(value)
        })
      })
    }
  }
  reject(reason) {
    if (this.status === PENDING) {
      setTimeout(() => {
        this.status = REJECTED
        this.reason = reason
        this.onRejectedCallbacks.forEach(callback => {
          callback(reason)
        })
      })
    }
  }
  then(onFulfilled, onRejected) {
    onFulfilled = typeof onFulfilled === 'function' ? onFulfilled : value => value
    onRejected = typeof onRejected === 'function' ? onRejected : reason => { throw reason }
    if (this.status === PENDING) {
      this.onFulfilledCallbacks.push(onFulfilled)
      this.onRejectedCallbacks.push(onRejected)
    }
    if (this.status === FULFILLED) {
      setTimeout(() => {
        onFulfilled(this.value)
      })
    }
    if (this.status === REJECTED) {
      setTimeout(() => {
        onRejected(this.reason)
      })
    }
  }
}

console.log(1)
const p = new myPromise((resolve, reject) => {
  setTimeout(() => {
    console.log(2)
    resolve(3)
    console.log(4)
  })
})
p.then((value) => {
  console.log('value:' + value)
}, (reason) => {
  console.log(reason)
})
console.log(5)

// 结果
// 1
// 5
// 2
// 4
// value: 3
```
## `Promise.then()` 的链式调用
我们常常用到 new Promise().then().then()，这就是链式调用，用来解决回调地狱。  
根据`promise/A+ 2.2.7`规范理解：
* `then`方法本身会返回一个新的`Promise`对象，返回一个新的Promise以后它就有自己的then方法，这样就能实现无限的链式。
* 不论 `promise1` 被 `resolve()` 还是被 `reject()` 时 `promise2` 都会执行 `Promise` 解决过程：`[[Resolve]](promise2, x)`。  
我们把这个 `Promise` 解决过程：`[[Resolve]](promise2, x)` 命名为 `resolvePromise()` 方法，参数为 `(promise2, x, resolve, reject)` 即：
```js
/**
 * 对resolve()、reject() 进行改造增强 针对resolve()和reject()中不同值情况 进行处理
 * @param  {promise} promise2 promise1.then方法返回的新的promise对象
 * @param  {[type]} x         promise1中onFulfilled或onRejected的返回值
 * @param  {[type]} resolve   promise2的resolve方法
 * @param  {[type]} reject    promise2的reject方法
 */
function resolvePromise(promise2, x, resolve, reject) {}
```
接着就来实现一个链式调用，首先`then`方法中新写一个`Promise`实例并返回：
```js
then(onFulfilled, onRejected) {
    onFulfilled = typeof onFulfilled === 'function' ? onFulfilled : value => value
    onRejected = typeof onRejected === 'function' ? onRejected : reason => { throw reason }
    // 新增Promise实例并返回 顺便修改成if else-if
    const promise2 = new myPromise((resolve, reject) => {
      if (this.status === FULFILLED) {
        setTimeout(() => {
          onFulfilled(this.value)
        })
      } else if (this.status === REJECTED) {
        setTimeout(() => {
          onRejected(this.reason)
        })
      } else if (this.status === PENDING) {
        this.onFulfilledCallbacks.push(onFulfilled)
        this.onRejectedCallbacks.push(onRejected)
      }
    })
    return promise2
  }
```
`2.2.7.1规范` 如果 `onFulfilled` 或者 `onRejected` 返回一个值 `x` ，则运行下面的 `Promise 解决过程：[[Resolve]](promise2, x)`。

首先将返回值赋给x：
```js
const x = onFulfilled(this.value)

const x = onRejected(this.reason)
```
然后通过`Promise 解决过程：[[Resolve]](promise2, x)` 即 `resolvePromise`
```js
const PENDING = 'pending'
const FULFILLED = 'fulfilled'
const REJECTED = 'rejected'
class myPromise {
  ...

  then(onFulfilled, onRejected) {
    onFulfilled = typeof onFulfilled === 'function' ? onFulfilled : value => value
    onRejected = typeof onRejected === 'function' ? onRejected : reason => { throw reason }
    // 新增Promise实例并返回
    const promise2 = new myPromise((resolve, reject) => {
      if (this.status === FULFILLED) {
        setTimeout(() => {
          const x = onFulfilled(this.value)
          resolvePromise(promise2, x, resolve, reject)
        })
      } else if (this.status === REJECTED) {
        setTimeout(() => {
          const x = onRejected(this.reason)
          resolvePromise(promise2, x, resolve, reject)
        })
      } else if (this.status === PENDING) {
        this.onFulfilledCallbacks.push(onFulfilled)
        this.onRejectedCallbacks.push(onRejected)
      }
    })
    return promise2
  }
}

// 实现一个resolvePromise方法
function resolvePromise(promise2, x, resolve, reject) {}
```
处理`onFulfilled `和 `onRejected` 抛出的异常`error`, 返回`rejec(error)`。包含pending状态下存储的`onFulfilled `和 `onRejected`。
```js
const PENDING = 'pending'
const FULFILLED = 'fulfilled'
const REJECTED = 'rejected'
class myPromise {
  constructor(fn) {
    this.status = PENDING
    this.value = null
    this.reason = null
    this.onFulfilledCallbacks = []  // 保存成功回调
    this.onRejectedCallbacks = []  // 保存失败回调
    try {
      fn(this.resolve.bind(this), this.reject.bind(this))
    } catch (error) {
      this.reject(error) 
    }
  }
  resolve(value) {
    if (this.status === PENDING) {
      setTimeout(() => {
        this.status = FULFILLED
        this.value = value
        this.onFulfilledCallbacks.forEach(callback => {
          callback(value)
        })
      })
    }
  }
  reject(reason) {
    if (this.status === PENDING) {
      setTimeout(() => {
        this.status = REJECTED
        this.reason = reason
        this.onRejectedCallbacks.forEach(callback => {
          callback(reason)
        })
      })
    }
  }
  then(onFulfilled, onRejected) {
    onFulfilled = typeof onFulfilled === 'function' ? onFulfilled : value => value
    onRejected = typeof onRejected === 'function' ? onRejected : reason => { throw reason }
    // 新增Promise实例并返回
    const promise2 = new myPromise((resolve, reject) => {
      if (this.status === FULFILLED) {
        setTimeout(() => {
          try {
            const x = onFulfilled(this.value)
            resolvePromise(promise2, x, resolve, reject) 
          } catch (error) {
            reject(error)
          }
        })
      } else if (this.status === REJECTED) {
        setTimeout(() => {
          try {
            const x = onRejected(this.reason)
            resolvePromise(promise2, x, resolve, reject)
          } catch (error) {
            reject(error)
          }
        })
      } else if (this.status === PENDING) {
        this.onFulfilledCallbacks.push(() => {
          setTimeout(() => {
            try {
              const x = onFulfilled(this.value)
              resolvePromise(promise2, x, resolve, reject) 
            } catch (error) {
              reject(error)
            }
          })
        })
        this.onRejectedCallbacks.push(() => {
          setTimeout(() => {
            try {
              const x = onRejected(this.reason)
              resolvePromise(promise2, x, resolve, reject)
            } catch (error) {
              reject(error)
            }
          })
        })
      }
    })
    return promise2
  }
}

function resolvePromise(promise2, x, resolve, reject) {}
```
`then`方法搞定，下面书写`resolvePromise`方法。
## 实现 `resolvePromise` 方法
如果从`onFulfilled`或`onRejected`中返回的 `x` 就是`promise2`，会导致循环引用报错。例如：
```js
const promise = new Promise((resolve, reject) => {
  resolve(100)
})
const p1 = promise.then(value => {
  console.log(value)
  return p1
})
```
所以要先判断，提示错误信息：
```js
function resolvePromise(promise2, x, resolve, reject) {
  if ( x === promise2 ) {
    return reject(new TypeError('Chaining cycle detected for promise'))
  }
}
```
具体代码：
```js
function resolvePromise(promise2, x, resolve, reject) {
  // 如果从`onFulfilled`或`onRejected`中返回的 `x` 就是`promise2`，会导致循环引用报错
  if (x === promise2) {
    return reject(new TypeError('Chaining cycle detected for promise'))
  }
  let called = false // 避免被多次调用
  // x不是null 且x是对象或者函数
  if (x !== null && (typeof x === 'object' || typeof x === 'function')) {
    try {
      // A+规定，声明then = x的then方法
      let then = x.then
      // 如果then是函数，就默认是promise了
      if (typeof then === 'function') { 
        then.call(x, y => {
          // 成功和失败只能调用一个
          if (called) return
          called = true
          // resolve的结果依旧是promise 那就继续解析
          resolvePromise(promise2, y, resolve, reject)
        }, err => {
          // 成功和失败只能调用一个
          if (called) return;
          called = true;
          reject(err) // 失败了就失败了
        })
      } else {
        resolve(x)
      }
    } catch (e) {
      // 也属于失败
      if (called) return
      called = true
      // 取then出错了那就不要在继续执行了
      reject(e)
    }
  } else {
    resolve(x)
  }
}
```
## 完整代码
```js
const PENDING = 'pending'
const FULFILLED = 'fulfilled'
const REJECTED = 'rejected'
class myPromise {
  constructor(fn) {
    this.status = PENDING
    this.value = null
    this.reason = null
    this.onFulfilledCallbacks = []  // 保存成功回调
    this.onRejectedCallbacks = []  // 保存失败回调
    try {
      fn(this.resolve.bind(this), this.reject.bind(this))
    } catch (error) {
      this.reject(error) 
    }
  }
  resolve(value) {
    if (this.status === PENDING) {
      setTimeout(() => {
        this.status = FULFILLED
        this.value = value
        this.onFulfilledCallbacks.forEach(callback => {
          callback(value)
        })
      })
    }
  }
  reject(reason) {
    if (this.status === PENDING) {
      setTimeout(() => {
        this.status = REJECTED
        this.reason = reason
        this.onRejectedCallbacks.forEach(callback => {
          callback(reason)
        })
      })
    }
  }
  then(onFulfilled, onRejected) {
    onFulfilled = typeof onFulfilled === 'function' ? onFulfilled : value => value
    onRejected = typeof onRejected === 'function' ? onRejected : reason => { throw reason }
    // 新增Promise实例并返回
    const promise2 = new myPromise((resolve, reject) => {
      if (this.status === FULFILLED) {
        setTimeout(() => {
          try {
            const x = onFulfilled(this.value)
            resolvePromise(promise2, x, resolve, reject) 
          } catch (error) {
            reject(error)
          }
        })
      } else if (this.status === REJECTED) {
        setTimeout(() => {
          try {
            const x = onRejected(this.reason)
            resolvePromise(promise2, x, resolve, reject)
          } catch (error) {
            reject(error)
          }
        })
      } else if (this.status === PENDING) {
        this.onFulfilledCallbacks.push(() => {
          setTimeout(() => {
            try {
              const x = onFulfilled(this.value)
              resolvePromise(promise2, x, resolve, reject) 
            } catch (error) {
              reject(error)
            }
          })
        })
        this.onRejectedCallbacks.push(() => {
          setTimeout(() => {
            try {
              const x = onRejected(this.reason)
              resolvePromise(promise2, x, resolve, reject)
            } catch (error) {
              reject(error)
            }
          })
        })
      }
    })
    return promise2
  }
}

function resolvePromise(promise2, x, resolve, reject) {
  // 如果从`onFulfilled`或`onRejected`中返回的 `x` 就是`promise2`，会导致循环引用报错
  if (x === promise2) {
    return reject(new TypeError('Chaining cycle detected for promise'))
  }
  let called = false // 避免被多次调用
  // x不是null 且x是对象或者函数
  if (x !== null && (typeof x === 'object' || typeof x === 'function')) {
    try {
      // A+规定，声明then = x的then方法
      let then = x.then
      // 如果then是函数，就默认是promise了
      if (typeof then === 'function') { 
        then.call(x, y => {
          // 成功和失败只能调用一个
          if (called) return
          called = true
          // resolve的结果依旧是promise 那就继续解析
          resolvePromise(promise2, y, resolve, reject)
        }, err => {
          // 成功和失败只能调用一个
          if (called) return;
          called = true;
          reject(err) // 失败了就失败了
        })
      } else {
        resolve(x)
      }
    } catch (e) {
      // 也属于失败
      if (called) return
      called = true
      // 取then出错了那就不要在继续执行了
      reject(e)
    }
  } else {
    resolve(x)
  }
}
```
## Promise A+测试
用Promises/A+官方的测试工具 `promises-aplus-tests` 来对我们的`myPromise`进行测试  
1. 安装 `promises-aplus-tests`:
```shell
npm install promises-aplus-tests -D
```
2. 使用 CommonJS 对外暴露 myPromise 类
```js
class myPromise {
	...
}
function resolvePromise(promise2, x, resolve, reject) { 
	...
}
module.exports = myPromise
```
3. 实现静态方法 deferred
要使用 `promises-aplus-tests` 这个工具测试，必须实现一个静态方法`deferred()`，官方对这个方法：
```js
class myPromise {
	...
}
function resolvePromise(promise2, x, resolve, reject) { 
	...
}
myPromise.deferred = function () {
  const result = {}
  result.promise = new myPromise((resolve, reject) => {
    result.resolve = resolve
    result.reject = reject
  })
  return result
}
module.exports = myPromise
```
4. 配置 package.json
新建一个 package.json ，配置如下运行，通过官方872个测试用例：
```js
// package.json
{
  "devDependencies": {
    "promises-aplus-tests": "^2.1.2"
  },
  "scripts": {
    "test": "promises-aplus-tests myPromise"
  }
}

// npm run test
```
## 链接
* [Promises/A+](https://promisesaplus.com/)
* [【翻译】Promises/A+规范](https://www.ituring.com.cn/article/66566)
